2025-06-23 10:27:23,312 INFO    MainThread:2438117 [wandb_init.py:setup_run_log_directory():703] Logging user logs to /home/thiago-bittencourt/fc-projeto-final/wandb/run-20250623_102723-89s50yvd/logs/debug.log
2025-06-23 10:27:23,312 INFO    MainThread:2438117 [wandb_init.py:setup_run_log_directory():704] Logging internal logs to /home/thiago-bittencourt/fc-projeto-final/wandb/run-20250623_102723-89s50yvd/logs/debug-internal.log
2025-06-23 10:27:23,312 INFO    MainThread:2438117 [wandb_init.py:init():831] calling init triggers
2025-06-23 10:27:23,312 INFO    MainThread:2438117 [wandb_init.py:init():836] wandb.init called with sweep_config: {}
config: {'batch_size': 64, 'epochs': 20, 'learning_rate': 0.001, 'model': 'DCNN08', 'fault_type': 'ball', 'augmentation': 'time', '_wandb': {}}
2025-06-23 10:27:24,295 INFO    MainThread:2438117 [wandb_init.py:init():872] starting backend
2025-06-23 10:27:24,295 INFO    MainThread:2438117 [wandb_init.py:init():875] sending inform_init request
2025-06-23 10:27:24,297 INFO    MainThread:2438117 [wandb_init.py:init():883] backend started and connected
2025-06-23 10:27:24,299 INFO    MainThread:2438117 [wandb_run.py:_label_probe_notebook():1299] probe notebook
2025-06-23 10:27:24,299 INFO    MainThread:2438117 [wandb_init.py:init():956] updated telemetry
2025-06-23 10:27:24,310 INFO    MainThread:2438117 [wandb_init.py:init():980] communicating run to backend with 90.0 second timeout
2025-06-23 10:27:25,060 INFO    MainThread:2438117 [wandb_init.py:init():1032] starting run threads in backend
2025-06-23 10:27:25,113 INFO    MainThread:2438117 [wandb_run.py:_console_start():2453] atexit reg
2025-06-23 10:27:25,113 INFO    MainThread:2438117 [wandb_run.py:_redirect():2301] redirect: wrap_raw
2025-06-23 10:27:25,113 INFO    MainThread:2438117 [wandb_run.py:_redirect():2370] Wrapping output streams.
2025-06-23 10:27:25,113 INFO    MainThread:2438117 [wandb_run.py:_redirect():2393] Redirects installed.
2025-06-23 10:27:25,113 INFO    MainThread:2438117 [wandb_init.py:init():1078] run started, returning control to user process
2025-06-23 10:27:46,836 WARNING MsgRouterThr:2438117 [router.py:message_loop():63] [no run ID] message_loop has been closed
Traceback (most recent call last):
  File "/home/thiago-bittencourt/fc-projeto-final/.venv/lib/python3.12/site-packages/wandb/sdk/interface/router_sock.py", line 27, in _read_message
    return self._sock_client.read_server_response(timeout=1)
           ^^^^^^^^^^^^^^^^^^^^^^^^^^^^^^^^^^^^^^^^^^^^^^^^^
  File "/home/thiago-bittencourt/fc-projeto-final/.venv/lib/python3.12/site-packages/wandb/sdk/lib/sock_client.py", line 235, in read_server_response
    data = self._read_packet_bytes(timeout=timeout)
           ^^^^^^^^^^^^^^^^^^^^^^^^^^^^^^^^^^^^^^^^
  File "/home/thiago-bittencourt/fc-projeto-final/.venv/lib/python3.12/site-packages/wandb/sdk/lib/sock_client.py", line 220, in _read_packet_bytes
    raise SockClientClosedError
wandb.sdk.lib.sock_client.SockClientClosedError

The above exception was the direct cause of the following exception:

Traceback (most recent call last):
  File "/home/thiago-bittencourt/fc-projeto-final/.venv/lib/python3.12/site-packages/wandb/sdk/interface/router.py", line 56, in message_loop
    msg = self._read_message()
          ^^^^^^^^^^^^^^^^^^^^
  File "/home/thiago-bittencourt/fc-projeto-final/.venv/lib/python3.12/site-packages/wandb/sdk/interface/router_sock.py", line 29, in _read_message
    raise MessageRouterClosedError from e
wandb.sdk.interface.router.MessageRouterClosedError
2025-06-23 10:27:46,838 INFO    MsgRouterThr:2438117 [mailbox.py:close():129] [no run ID] Closing mailbox, abandoning 2 handles.
